<<< PROJECT PART I -- process set (n=20) with 12 CPU-bound processes >>>
I/O-bound process A: arrival time 45ms; 94 CPU bursts
I/O-bound process B: arrival time 190ms; 51 CPU bursts
I/O-bound process C: arrival time 142ms; 32 CPU bursts
I/O-bound process D: arrival time 41ms; 85 CPU bursts
I/O-bound process E: arrival time 2ms; 50 CPU bursts
I/O-bound process F: arrival time 119ms; 91 CPU bursts
I/O-bound process G: arrival time 33ms; 69 CPU bursts
I/O-bound process H: arrival time 88ms; 42 CPU bursts
CPU-bound process I: arrival time 67ms; 75 CPU bursts
CPU-bound process J: arrival time 73ms; 90 CPU bursts
CPU-bound process K: arrival time 53ms; 89 CPU bursts
CPU-bound process L: arrival time 80ms; 80 CPU bursts
CPU-bound process M: arrival time 178ms; 18 CPU bursts
CPU-bound process N: arrival time 80ms; 18 CPU bursts
CPU-bound process O: arrival time 131ms; 3 CPU bursts
CPU-bound process P: arrival time 109ms; 75 CPU bursts
CPU-bound process Q: arrival time 99ms; 59 CPU bursts
CPU-bound process R: arrival time 7ms; 99 CPU bursts
CPU-bound process S: arrival time 165ms; 40 CPU bursts
CPU-bound process T: arrival time 53ms; 99 CPU bursts

<<< PROJECT PART II -- t_cs=4ms; alpha=0.96; t_slice=64ms >>>
time 0ms: Simulator started for FCFS [Q <empty>]
time 2ms: Process E (tau 100ms) arrived; added to ready queue [Q E]
time 4ms: Process E (tau 100ms) started using the CPU for 8ms burst [Q <empty>]
time 7ms: Process R (tau 100ms) arrived; added to ready queue [Q R]
time 12ms: Process E (tau 100ms) completed a CPU burst; 49 bursts to go [Q R]
time 12ms: Recalculating tau for process E: old tau 100ms ==> new tau 12ms [Q R]
time 12ms: Process E switching out of CPU; blocking on I/O until time 1224ms [Q R]
time 16ms: Process R (tau 100ms) started using the CPU for 356ms burst [Q <empty>]
time 33ms: Process G (tau 100ms) arrived; added to ready queue [Q G]
time 41ms: Process D (tau 100ms) arrived; added to ready queue [Q D G]
time 45ms: Process A (tau 100ms) arrived; added to ready queue [Q A D G]
time 53ms: Process K (tau 100ms) arrived; added to ready queue [Q A D G K]
time 53ms: Process T (tau 100ms) arrived; added to ready queue [Q A D G K T]
time 67ms: Process I (tau 100ms) arrived; added to ready queue [Q A D G I K T]
time 73ms: Process J (tau 100ms) arrived; added to ready queue [Q A D G I J K T]
time 80ms: Process L (tau 100ms) arrived; added to ready queue [Q A D G I J K L T]
time 80ms: Process N (tau 100ms) arrived; added to ready queue [Q A D G I J K L N T]
time 88ms: Process H (tau 100ms) arrived; added to ready queue [Q A D G H I J K L N T]
time 99ms: Process Q (tau 100ms) arrived; added to ready queue [Q A D G H I J K L N Q T]
time 109ms: Process P (tau 100ms) arrived; added to ready queue [Q A D G H I J K L N P Q T]
time 119ms: Process F (tau 100ms) arrived; added to ready queue [Q A D F G H I J K L N P Q T]
time 131ms: Process O (tau 100ms) arrived; added to ready queue [Q A D F G H I J K L N O P Q T]
time 142ms: Process C (tau 100ms) arrived; added to ready queue [Q A C D F G H I J K L N O P Q T]
time 165ms: Process S (tau 100ms) arrived; added to ready queue [Q A C D F G H I J K L N O P Q S T]
time 178ms: Process M (tau 100ms) arrived; added to ready queue [Q A C D F G H I J K L M N O P Q S T]
time 190ms: Process B (tau 100ms) arrived; added to ready queue [Q A B C D F G H I J K L M N O P Q S T]
time 372ms: Process R (tau 100ms) completed a CPU burst; 98 bursts to go [Q A B C D F G H I J K L M N O P Q S T]
time 372ms: Recalculating tau for process R: old tau 100ms ==> new tau 346ms [Q A B C D F G H I J K L M N O P Q S T]
time 372ms: Process R switching out of CPU; blocking on I/O until time 474ms [Q A B C D F G H I J K L M N O P Q S T]
time 376ms: Process G (tau 100ms) started using the CPU for 297ms burst [Q A B C D F H I J K L M N O P Q S T]
time 474ms: Process R (tau 346ms) completed I/O; added to ready queue [Q A B C D F H I J K L M N O P Q S T R]
time 673ms: Process G (tau 100ms) completed a CPU burst; 68 bursts to go [Q A B C D F H I J K L M N O P Q S T R]
time 673ms: Recalculating tau for process G: old tau 100ms ==> new tau 290ms [Q A B C D F H I J K L M N O P Q S T R]
time 673ms: Process G switching out of CPU; blocking on I/O until time 1005ms [Q A B C D F H I J K L M N O P Q S T R]
time 677ms: Process D (tau 100ms) started using the CPU for 446ms burst [Q A B C F H I J K L M N O P Q S T R]
time 1005ms: Process G (tau 290ms) completed I/O; added to ready queue [Q A B C F H I J K L M N O P Q S T G R]
time 1123ms: Process D (tau 100ms) completed a CPU burst; 84 bursts to go [Q A B C F H I J K L M N O P Q S T G R]
time 1123ms: Recalculating tau for process D: old tau 100ms ==> new tau 433ms [Q A B C F H I J K L M N O P Q S T G R]
time 1123ms: Process D switching out of CPU; blocking on I/O until time 1825ms [Q A B C F H I J K L M N O P Q S T G R]
time 1127ms: Process A (tau 100ms) started using the CPU for 49ms burst [Q B C F H I J K L M N O P Q S T G R]
time 1176ms: Process A (tau 100ms) completed a CPU burst; 93 bursts to go [Q B C F H I J K L M N O P Q S T G R]
time 1176ms: Recalculating tau for process A: old tau 100ms ==> new tau 52ms [Q B C F H I J K L M N O P Q S T G R]
time 1176ms: Process A switching out of CPU; blocking on I/O until time 1968ms [Q B C F H I J K L M N O P Q S T G R]
time 1180ms: Process K (tau 100ms) started using the CPU for 56ms burst [Q B C F H I J L M N O P Q S T G R]
time 1224ms: Process E (tau 12ms) completed I/O; added to ready queue [Q E B C F H I J L M N O P Q S T G R]
time 1236ms: Process K (tau 100ms) completed a CPU burst; 88 bursts to go [Q E B C F H I J L M N O P Q S T G R]
time 1236ms: Recalculating tau for process K: old tau 100ms ==> new tau 58ms [Q E B C F H I J L M N O P Q S T G R]
time 1236ms: Process K switching out of CPU; blocking on I/O until time 1315ms [Q E B C F H I J L M N O P Q S T G R]
time 1240ms: Process T (tau 100ms) started using the CPU for 464ms burst [Q E B C F H I J L M N O P Q S G R]
time 1315ms: Process K (tau 58ms) completed I/O; added to ready queue [Q E K B C F H I J L M N O P Q S G R]
time 1704ms: Process T (tau 100ms) completed a CPU burst; 98 bursts to go [Q E K B C F H I J L M N O P Q S G R]
time 1704ms: Recalculating tau for process T: old tau 100ms ==> new tau 450ms [Q E K B C F H I J L M N O P Q S G R]
time 1704ms: Process T switching out of CPU; blocking on I/O until time 2013ms [Q E K B C F H I J L M N O P Q S G R]
time 1708ms: Process I (tau 100ms) started using the CPU for 684ms burst [Q E K B C F H J L M N O P Q S G R]
time 1825ms: Process D (tau 433ms) completed I/O; added to ready queue [Q E K B C F H J L M N O P Q S G R D]
time 1968ms: Process A (tau 52ms) completed I/O; added to ready queue [Q E A K B C F H J L M N O P Q S G R D]
time 2013ms: Process T (tau 450ms) completed I/O; added to ready queue [Q E A K B C F H J L M N O P Q S G R D T]
time 2392ms: Process I (tau 100ms) completed a CPU burst; 74 bursts to go [Q E A K B C F H J L M N O P Q S G R D T]
time 2392ms: Recalculating tau for process I: old tau 100ms ==> new tau 661ms [Q E A K B C F H J L M N O P Q S G R D T]
time 2392ms: Process I switching out of CPU; blocking on I/O until time 2536ms [Q E A K B C F H J L M N O P Q S G R D T]
time 2396ms: Process J (tau 100ms) started using the CPU for 352ms burst [Q E A K B C F H L M N O P Q S G R D T]
time 2536ms: Process I (tau 661ms) completed I/O; added to ready queue [Q E A K B C F H L M N O P Q S G R D T I]
time 2748ms: Process J (tau 100ms) completed a CPU burst; 89 bursts to go [Q E A K B C F H L M N O P Q S G R D T I]
time 2748ms: Recalculating tau for process J: old tau 100ms ==> new tau 342ms [Q E A K B C F H L M N O P Q S G R D T I]
time 2748ms: Process J switching out of CPU; blocking on I/O until time 2900ms [Q E A K B C F H L M N O P Q S G R D T I]
time 2752ms: Process L (tau 100ms) started using the CPU for 252ms burst [Q E A K B C F H M N O P Q S G R D T I]
time 2900ms: Process J (tau 342ms) completed I/O; added to ready queue [Q E A K B C F H M N O P Q S G J R D T I]
time 3004ms: Process L (tau 100ms) completed a CPU burst; 79 bursts to go [Q E A K B C F H M N O P Q S G J R D T I]
time 3004ms: Recalculating tau for process L: old tau 100ms ==> new tau 246ms [Q E A K B C F H M N O P Q S G J R D T I]
time 3004ms: Process L switching out of CPU; blocking on I/O until time 3263ms [Q E A K B C F H M N O P Q S G J R D T I]
time 3008ms: Process N (tau 100ms) started using the CPU for 20ms burst [Q E A K B C F H M O P Q S G J R D T I]
time 3028ms: Process N (tau 100ms) completed a CPU burst; 17 bursts to go [Q E A K B C F H M O P Q S G J R D T I]
time 3028ms: Recalculating tau for process N: old tau 100ms ==> new tau 24ms [Q E A K B C F H M O P Q S G J R D T I]
time 3028ms: Process N switching out of CPU; blocking on I/O until time 3182ms [Q E A K B C F H M O P Q S G J R D T I]
time 3032ms: Process H (tau 100ms) started using the CPU for 106ms burst [Q E A K B C F M O P Q S G J R D T I]
time 3138ms: Process H (tau 100ms) completed a CPU burst; 41 bursts to go [Q E A K B C F M O P Q S G J R D T I]
time 3138ms: Recalculating tau for process H: old tau 100ms ==> new tau 106ms [Q E A K B C F M O P Q S G J R D T I]
time 3138ms: Process H switching out of CPU; blocking on I/O until time 3190ms [Q E A K B C F M O P Q S G J R D T I]
time 3142ms: Process Q (tau 100ms) started using the CPU for 88ms burst [Q E A K B C F M O P S G J R D T I]
time 3182ms: Process N (tau 24ms) completed I/O; added to ready queue [Q E N A K B C F M O P S G J R D T I]
time 3190ms: Process H (tau 106ms) completed I/O; added to ready queue [Q E N A K B C F M O P S H G J R D T I]
time 3230ms: Process Q (tau 100ms) completed a CPU burst; 58 bursts to go [Q E N A K B C F M O P S H G J R D T I]
time 3230ms: Recalculating tau for process Q: old tau 100ms ==> new tau 89ms [Q E N A K B C F M O P S H G J R D T I]
time 3230ms: Process Q switching out of CPU; blocking on I/O until time 3539ms [Q E N A K B C F M O P S H G J R D T I]
time 3234ms: Process P (tau 100ms) started using the CPU for 72ms burst [Q E N A K B C F M O S H G J R D T I]
time 3263ms: Process L (tau 246ms) completed I/O; added to ready queue [Q E N A K B C F M O S H L G J R D T I]
time 3306ms: Process P (tau 100ms) completed a CPU burst; 74 bursts to go [Q E N A K B C F M O S H L G J R D T I]
time 3306ms: Recalculating tau for process P: old tau 100ms ==> new tau 74ms [Q E N A K B C F M O S H L G J R D T I]
time 3306ms: Process P switching out of CPU; blocking on I/O until time 3315ms [Q E N A K B C F M O S H L G J R D T I]
time 3310ms: Process F (tau 100ms) started using the CPU for 58ms burst [Q E N A K B C M O S H L G J R D T I]
time 3315ms: Process P (tau 74ms) completed I/O; added to ready queue [Q E N A K P B C M O S H L G J R D T I]
time 3368ms: Process F (tau 100ms) completed a CPU burst; 90 bursts to go [Q E N A K P B C M O S H L G J R D T I]
time 3368ms: Recalculating tau for process F: old tau 100ms ==> new tau 60ms [Q E N A K P B C M O S H L G J R D T I]
time 3368ms: Process F switching out of CPU; blocking on I/O until time 3830ms [Q E N A K P B C M O S H L G J R D T I]
time 3372ms: Process O (tau 100ms) started using the CPU for 200ms burst [Q E N A K P B C M S H L G J R D T I]
time 3539ms: Process Q (tau 89ms) completed I/O; added to ready queue [Q E N A K P Q B C M S H L G J R D T I]
time 3572ms: Process O (tau 100ms) completed a CPU burst; 2 bursts to go [Q E N A K P Q B C M S H L G J R D T I]
time 3572ms: Recalculating tau for process O: old tau 100ms ==> new tau 196ms [Q E N A K P Q B C M S H L G J R D T I]
time 3572ms: Process O switching out of CPU; blocking on I/O until time 3766ms [Q E N A K P Q B C M S H L G J R D T I]
time 3576ms: Process C (tau 100ms) started using the CPU for 63ms burst [Q E N A K P Q B M S H L G J R D T I]
time 3639ms: Process C (tau 100ms) completed a CPU burst; 31 bursts to go [Q E N A K P Q B M S H L G J R D T I]
time 3639ms: Recalculating tau for process C: old tau 100ms ==> new tau 65ms [Q E N A K P Q B M S H L G J R D T I]
time 3639ms: Process C switching out of CPU; blocking on I/O until time 3741ms [Q E N A K P Q B M S H L G J R D T I]
time 3643ms: Process S (tau 100ms) started using the CPU for 840ms burst [Q E N A K P Q B M H L G J R D T I]
time 3741ms: Process C (tau 65ms) completed I/O; added to ready queue [Q E N A K C P Q B M H L G J R D T I]
time 3766ms: Process O (tau 196ms) completed I/O; added to ready queue [Q E N A K C P Q B M H O L G J R D T I]
time 3830ms: Process F (tau 60ms) completed I/O; added to ready queue [Q E N A K F C P Q B M H O L G J R D T I]
time 4483ms: Process S (tau 100ms) completed a CPU burst; 39 bursts to go [Q E N A K F C P Q B M H O L G J R D T I]
time 4483ms: Recalculating tau for process S: old tau 100ms ==> new tau 811ms [Q E N A K F C P Q B M H O L G J R D T I]
time 4483ms: Process S switching out of CPU; blocking on I/O until time 4755ms [Q E N A K F C P Q B M H O L G J R D T I]
time 4487ms: Process M (tau 100ms) started using the CPU for 1160ms burst [Q E N A K F C P Q B H O L G J R D T I]
time 4755ms: Process S (tau 811ms) completed I/O; added to ready queue [Q E N A K F C P Q B H O L G J R D T I S]
time 5647ms: Process M (tau 100ms) completed a CPU burst; 17 bursts to go [Q E N A K F C P Q B H O L G J R D T I S]
time 5647ms: Recalculating tau for process M: old tau 100ms ==> new tau 1118ms [Q E N A K F C P Q B H O L G J R D T I S]
time 5647ms: Process M switching out of CPU; blocking on I/O until time 5931ms [Q E N A K F C P Q B H O L G J R D T I S]
time 5651ms: Process B (tau 100ms) started using the CPU for 15ms burst [Q E N A K F C P Q H O L G J R D T I S]
time 5666ms: Process B (tau 100ms) completed a CPU burst; 50 bursts to go [Q E N A K F C P Q H O L G J R D T I S]
time 5666ms: Recalculating tau for process B: old tau 100ms ==> new tau 19ms [Q E N A K F C P Q H O L G J R D T I S]
time 5666ms: Process B switching out of CPU; blocking on I/O until time 6818ms [Q E N A K F C P Q H O L G J R D T I S]
time 5670ms: Process R (tau 346ms) started using the CPU for 772ms burst [Q E N A K F C P Q H O L G J D T I S]
time 5931ms: Process M (tau 1118ms) completed I/O; added to ready queue [Q E N A K F C P Q H O L G J D T I S M]
time 6442ms: Process R (tau 346ms) completed a CPU burst; 97 bursts to go [Q E N A K F C P Q H O L G J D T I S M]
time 6442ms: Recalculating tau for process R: old tau 346ms ==> new tau 755ms [Q E N A K F C P Q H O L G J D T I S M]
time 6442ms: Process R switching out of CPU; blocking on I/O until time 6996ms [Q E N A K F C P Q H O L G J D T I S M]
time 6446ms: Process G (tau 290ms) started using the CPU for 30ms burst [Q E N A K F C P Q H O L J D T I S M]
time 6476ms: Process G (tau 290ms) completed a CPU burst; 67 bursts to go [Q E N A K F C P Q H O L J D T I S M]
time 6476ms: Recalculating tau for process G: old tau 290ms ==> new tau 41ms [Q E N A K F C P Q H O L J D T I S M]
time 6476ms: Process G switching out of CPU; blocking on I/O until time 6658ms [Q E N A K F C P Q H O L J D T I S M]
time 6480ms: Process E (tau 12ms) started using the CPU for 3ms burst [Q N A K F C P Q H O L J D T I S M]
time 6483ms: Process E (tau 12ms) completed a CPU burst; 48 bursts to go [Q N A K F C P Q H O L J D T I S M]
time 6483ms: Recalculating tau for process E: old tau 12ms ==> new tau 4ms [Q N A K F C P Q H O L J D T I S M]
time 6483ms: Process E switching out of CPU; blocking on I/O until time 7855ms [Q N A K F C P Q H O L J D T I S M]
time 6487ms: Process K (tau 58ms) started using the CPU for 28ms burst [Q N A F C P Q H O L J D T I S M]
time 6515ms: Process K (tau 58ms) completed a CPU burst; 87 bursts to go [Q N A F C P Q H O L J D T I S M]
time 6515ms: Recalculating tau for process K: old tau 58ms ==> new tau 30ms [Q N A F C P Q H O L J D T I S M]
time 6515ms: Process K switching out of CPU; blocking on I/O until time 6587ms [Q N A F C P Q H O L J D T I S M]
time 6519ms: Process D (tau 433ms) started using the CPU for 3ms burst [Q N A F C P Q H O L J T I S M]
time 6522ms: Process D (tau 433ms) completed a CPU burst; 83 bursts to go [Q N A F C P Q H O L J T I S M]
time 6522ms: Recalculating tau for process D: old tau 433ms ==> new tau 21ms [Q N A F C P Q H O L J T I S M]
time 6522ms: Process D switching out of CPU; blocking on I/O until time 7474ms [Q N A F C P Q H O L J T I S M]
time 6526ms: Process A (tau 52ms) started using the CPU for 274ms burst [Q N F C P Q H O L J T I S M]
time 6587ms: Process K (tau 30ms) completed I/O; added to ready queue [Q N K F C P Q H O L J T I S M]
time 6658ms: Process G (tau 41ms) completed I/O; added to ready queue [Q N K G F C P Q H O L J T I S M]
time 6800ms: Process A (tau 52ms) completed a CPU burst; 92 bursts to go [Q N K G F C P Q H O L J T I S M]
time 6800ms: Recalculating tau for process A: old tau 52ms ==> new tau 266ms [Q N K G F C P Q H O L J T I S M]
time 6800ms: Process A switching out of CPU; blocking on I/O until time 7652ms [Q N K G F C P Q H O L J T I S M]
time 6804ms: Process T (tau 450ms) started using the CPU for 408ms burst [Q N K G F C P Q H O L J I S M]
time 6818ms: Process B (tau 19ms) completed I/O; added to ready queue [Q B N K G F C P Q H O L J I S M]
time 6996ms: Process R (tau 755ms) completed I/O; added to ready queue [Q B N K G F C P Q H O L J I R S M]
time 7212ms: Process T (tau 450ms) completed a CPU burst; 97 bursts to go [Q B N K G F C P Q H O L J I R S M]
time 7212ms: Recalculating tau for process T: old tau 450ms ==> new tau 410ms [Q B N K G F C P Q H O L J I R S M]
time 7212ms: Process T switching out of CPU; blocking on I/O until time 7234ms [Q B N K G F C P Q H O L J I R S M]
time 7216ms: Process I (tau 661ms) started using the CPU for 1000ms burst [Q B N K G F C P Q H O L J R S M]
time 7234ms: Process T (tau 410ms) completed I/O; added to ready queue [Q B N K G F C P Q H O L J T R S M]
time 7474ms: Process D (tau 21ms) completed I/O; added to ready queue [Q B D N K G F C P Q H O L J T R S M]
time 7652ms: Process A (tau 266ms) completed I/O; added to ready queue [Q B D N K G F C P Q H O L A J T R S M]
time 7855ms: Process E (tau 4ms) completed I/O; added to ready queue [Q E B D N K G F C P Q H O L A J T R S M]
time 8216ms: Process I (tau 661ms) completed a CPU burst; 73 bursts to go [Q E B D N K G F C P Q H O L A J T R S M]
time 8216ms: Recalculating tau for process I: old tau 661ms ==> new tau 987ms [Q E B D N K G F C P Q H O L A J T R S M]
time 8216ms: Process I switching out of CPU; blocking on I/O until time 8345ms [Q E B D N K G F C P Q H O L A J T R S M]
time 8220ms: Process J (tau 342ms) started using the CPU for 44ms burst [Q E B D N K G F C P Q H O L A T R S M]
time 8264ms: Process J (tau 342ms) completed a CPU burst; 88 bursts to go [Q E B D N K G F C P Q H O L A T R S M]
time 8264ms: Recalculating tau for process J: old tau 342ms ==> new tau 56ms [Q E B D N K G F C P Q H O L A T R S M]
time 8264ms: Process J switching out of CPU; blocking on I/O until time 8283ms [Q E B D N K G F C P Q H O L A T R S M]
time 8268ms: Process N (tau 24ms) started using the CPU for 372ms burst [Q E B D K G F C P Q H O L A T R S M]
time 8283ms: Process J (tau 56ms) completed I/O; added to ready queue [Q E B D K G J F C P Q H O L A T R S M]
time 8345ms: Process I (tau 987ms) completed I/O; added to ready queue [Q E B D K G J F C P Q H O L A T R S I M]
time 8640ms: Process N (tau 24ms) completed a CPU burst; 16 bursts to go [Q E B D K G J F C P Q H O L A T R S I M]
time 8640ms: Recalculating tau for process N: old tau 24ms ==> new tau 359ms [Q E B D K G J F C P Q H O L A T R S I M]
time 8640ms: Process N switching out of CPU; blocking on I/O until time 9042ms [Q E B D K G J F C P Q H O L A T R S I M]
time 8644ms: Process H (tau 106ms) started using the CPU for 62ms burst [Q E B D K G J F C P Q O L A T R S I M]
time 8706ms: Process H (tau 106ms) completed a CPU burst; 40 bursts to go [Q E B D K G J F C P Q O L A T R S I M]
time 8706ms: Recalculating tau for process H: old tau 106ms ==> new tau 64ms [Q E B D K G J F C P Q O L A T R S I M]
time 8706ms: Process H switching out of CPU; blocking on I/O until time 12708ms [Q E B D K G J F C P Q O L A T R S I M]
time 8710ms: Process L (tau 246ms) started using the CPU for 720ms burst [Q E B D K G J F C P Q O A T R S I M]
time 9042ms: Process N (tau 359ms) completed I/O; added to ready queue [Q E B D K G J F C P Q O A N T R S I M]
time 9430ms: Process L (tau 246ms) completed a CPU burst; 78 bursts to go [Q E B D K G J F C P Q O A N T R S I M]
time 9430ms: Recalculating tau for process L: old tau 246ms ==> new tau 702ms [Q E B D K G J F C P Q O A N T R S I M]
time 9430ms: Process L switching out of CPU; blocking on I/O until time 9474ms [Q E B D K G J F C P Q O A N T R S I M]
time 9434ms: Process P (tau 74ms) started using the CPU for 32ms burst [Q E B D K G J F C Q O A N T R S I M]
time 9466ms: Process P (tau 74ms) completed a CPU burst; 73 bursts to go [Q E B D K G J F C Q O A N T R S I M]
time 9466ms: Recalculating tau for process P: old tau 74ms ==> new tau 34ms [Q E B D K G J F C Q O A N T R S I M]
time 9466ms: Process P switching out of CPU; blocking on I/O until time 9788ms [Q E B D K G J F C Q O A N T R S I M]
time 9470ms: Process Q (tau 89ms) started using the CPU for 268ms burst [Q E B D K G J F C O A N T R S I M]
time 9474ms: Process L (tau 702ms) completed I/O; added to ready queue [Q E B D K G J F C O A N T L R S I M]
time 9738ms: Process Q (tau 89ms) completed a CPU burst; 57 bursts to go [Q E B D K G J F C O A N T L R S I M]
time 9738ms: Recalculating tau for process Q: old tau 89ms ==> new tau 261ms [Q E B D K G J F C O A N T L R S I M]
time 9738ms: Process Q switching out of CPU; blocking on I/O until time 9755ms [Q E B D K G J F C O A N T L R S I M]
time 9742ms: Process C (tau 65ms) started using the CPU for 63ms burst [Q E B D K G J F O A N T L R S I M]
time 9755ms: Process Q (tau 261ms) completed I/O; added to ready queue [Q E B D K G J F O Q A N T L R S I M]
time 9788ms: Process P (tau 34ms) completed I/O; added to ready queue [Q E B D K P G J F O Q A N T L R S I M]
time 9805ms: Process C (tau 65ms) completed a CPU burst; 30 bursts to go [Q E B D K P G J F O Q A N T L R S I M]
time 9805ms: Recalculating tau for process C: old tau 65ms ==> new tau 64ms [Q E B D K P G J F O Q A N T L R S I M]
time 9805ms: Process C switching out of CPU; blocking on I/O until time 11247ms [Q E B D K P G J F O Q A N T L R S I M]
time 9809ms: Process O (tau 196ms) started using the CPU for 4ms burst [Q E B D K P G J F Q A N T L R S I M]
time 9813ms: Process O (tau 196ms) completed a CPU burst; 1 bursts to go [Q E B D K P G J F Q A N T L R S I M]
time 9813ms: Recalculating tau for process O: old tau 196ms ==> new tau 12ms [Q E B D K P G J F Q A N T L R S I M]
time 9813ms: Process O switching out of CPU; blocking on I/O until time 10055ms [Q E B D K P G J F Q A N T L R S I M]
time 9817ms: Process F (tau 60ms) started using the CPU for 31ms burst [Q E B D K P G J Q A N T L R S I M]
time 9848ms: Process F (tau 60ms) completed a CPU burst; 89 bursts to go [Q E B D K P G J Q A N T L R S I M]
time 9848ms: Recalculating tau for process F: old tau 60ms ==> new tau 33ms [Q E B D K P G J Q A N T L R S I M]
time 9848ms: Process F switching out of CPU; blocking on I/O until time 10100ms [Q E B D K P G J Q A N T L R S I M]
time 9852ms: Process S (tau 811ms) started using the CPU for 484ms burst [Q E B D K P G J Q A N T L R I M]
time 14969ms: Process O terminated [Q F C H L G B N K M R A P E J I D S T]
time 97577ms: Process N terminated [Q G F D C I L H T A J E B P S Q]
time 103395ms: Process M terminated [Q H A B F K G I E D L J R S P T Q]
time 186027ms: Process C terminated [Q D I F H P B E K R L Q S J]
time 202882ms: Process S terminated [Q B A E D G T R F P Q I J K L]
time 234411ms: Process H terminated [Q D G P B J K Q R I L]
time 268693ms: Process E terminated [Q F G B R D I L Q A P T J K]
time 270777ms: Process B terminated [Q R A G J F I T Q L P K]
time 275557ms: Process Q terminated [Q D L F P I T R J]
time 317382ms: Process P terminated [Q A I J L K T R D G F]
time 323872ms: Process I terminated [Q A D G F J K L T R]
time 332716ms: Process G terminated [Q D F K L J]
time 338644ms: Process L terminated [Q T F J R]
time 354283ms: Process J terminated [Q D A K T R]
time 357542ms: Process K terminated [Q A R]
time 366589ms: Process T terminated [Q A]
time 368767ms: Process R terminated [Q F]
time 370604ms: Process F terminated [Q <empty>]
time 383455ms: Process D terminated [Q <empty>]
time 384019ms: Process A terminated [Q <empty>]
time 384021ms: Simulator ended for FCFS [Q <empty>]

time 0ms: Simulator started for SJF [Q <empty>]
time 2ms: Process E (tau 100ms) arrived; added to ready queue [Q E]
time 4ms: Process E (tau 100ms) started using the CPU for 8ms burst [Q <empty>]
time 7ms: Process R (tau 100ms) arrived; added to ready queue [Q R]
time 12ms: Process E (tau 100ms) completed a CPU burst; 49 bursts to go [Q R]
time 12ms: Recalculating tau for process E: old tau 100ms ==> new tau 12ms [Q R]
time 12ms: Process E switching out of CPU; blocking on I/O until time 1224ms [Q R]
time 16ms: Process R (tau 100ms) started using the CPU for 356ms burst [Q <empty>]
time 33ms: Process G (tau 100ms) arrived; added to ready queue [Q G]
time 41ms: Process D (tau 100ms) arrived; added to ready queue [Q D G]
time 45ms: Process A (tau 100ms) arrived; added to ready queue [Q A D G]
time 53ms: Process K (tau 100ms) arrived; added to ready queue [Q A D G K]
time 53ms: Process T (tau 100ms) arrived; added to ready queue [Q A D G K T]
time 67ms: Process I (tau 100ms) arrived; added to ready queue [Q A D G I K T]
time 73ms: Process J (tau 100ms) arrived; added to ready queue [Q A D G I J K T]
time 80ms: Process L (tau 100ms) arrived; added to ready queue [Q A D G I J K L T]
time 80ms: Process N (tau 100ms) arrived; added to ready queue [Q A D G I J K L N T]
time 88ms: Process H (tau 100ms) arrived; added to ready queue [Q A D G H I J K L N T]
time 99ms: Process Q (tau 100ms) arrived; added to ready queue [Q A D G H I J K L N Q T]
time 109ms: Process P (tau 100ms) arrived; added to ready queue [Q A D G H I J K L N P Q T]
time 119ms: Process F (tau 100ms) arrived; added to ready queue [Q A D F G H I J K L N P Q T]
time 131ms: Process O (tau 100ms) arrived; added to ready queue [Q A D F G H I J K L N O P Q T]
time 142ms: Process C (tau 100ms) arrived; added to ready queue [Q A C D F G H I J K L N O P Q T]
time 165ms: Process S (tau 100ms) arrived; added to ready queue [Q A C D F G H I J K L N O P Q S T]
time 178ms: Process M (tau 100ms) arrived; added to ready queue [Q A C D F G H I J K L M N O P Q S T]
time 190ms: Process B (tau 100ms) arrived; added to ready queue [Q A B C D F G H I J K L M N O P Q S T]
time 372ms: Process R (tau 100ms) completed a CPU burst; 98 bursts to go [Q A B C D F G H I J K L M N O P Q S T]
time 372ms: Recalculating tau for process R: old tau 100ms ==> new tau 346ms [Q A B C D F G H I J K L M N O P Q S T]
time 372ms: Process R switching out of CPU; blocking on I/O until time 474ms [Q A B C D F G H I J K L M N O P Q S T]
time 376ms: Process A (tau 100ms) started using the CPU for 49ms burst [Q B C D F G H I J K L M N O P Q S T]
time 425ms: Process A (tau 100ms) completed a CPU burst; 93 bursts to go [Q B C D F G H I J K L M N O P Q S T]
time 425ms: Recalculating tau for process A: old tau 100ms ==> new tau 52ms [Q B C D F G H I J K L M N O P Q S T]
time 425ms: Process A switching out of CPU; blocking on I/O until time 1217ms [Q B C D F G H I J K L M N O P Q S T]
time 429ms: Process B (tau 100ms) started using the CPU for 15ms burst [Q C D F G H I J K L M N O P Q S T]
time 444ms: Process B (tau 100ms) completed a CPU burst; 50 bursts to go [Q C D F G H I J K L M N O P Q S T]
time 444ms: Recalculating tau for process B: old tau 100ms ==> new tau 19ms [Q C D F G H I J K L M N O P Q S T]
time 444ms: Process B switching out of CPU; blocking on I/O until time 1596ms [Q C D F G H I J K L M N O P Q S T]
time 448ms: Process C (tau 100ms) started using the CPU for 63ms burst [Q D F G H I J K L M N O P Q S T]
time 474ms: Process R (tau 346ms) completed I/O; added to ready queue [Q D F G H I J K L M N O P Q S T R]
time 511ms: Process C (tau 100ms) completed a CPU burst; 31 bursts to go [Q D F G H I J K L M N O P Q S T R]
time 511ms: Recalculating tau for process C: old tau 100ms ==> new tau 65ms [Q D F G H I J K L M N O P Q S T R]
time 511ms: Process C switching out of CPU; blocking on I/O until time 613ms [Q D F G H I J K L M N O P Q S T R]
time 515ms: Process D (tau 100ms) started using the CPU for 446ms burst [Q F G H I J K L M N O P Q S T R]
time 613ms: Process C (tau 65ms) completed I/O; added to ready queue [Q C F G H I J K L M N O P Q S T R]
time 961ms: Process D (tau 100ms) completed a CPU burst; 84 bursts to go [Q C F G H I J K L M N O P Q S T R]
time 961ms: Recalculating tau for process D: old tau 100ms ==> new tau 433ms [Q C F G H I J K L M N O P Q S T R]
time 961ms: Process D switching out of CPU; blocking on I/O until time 1663ms [Q C F G H I J K L M N O P Q S T R]
time 965ms: Process C (tau 65ms) started using the CPU for 63ms burst [Q F G H I J K L M N O P Q S T R]
time 1028ms: Process C (tau 65ms) completed a CPU burst; 30 bursts to go [Q F G H I J K L M N O P Q S T R]
time 1028ms: Recalculating tau for process C: old tau 65ms ==> new tau 64ms [Q F G H I J K L M N O P Q S T R]
time 1028ms: Process C switching out of CPU; blocking on I/O until time 2470ms [Q F G H I J K L M N O P Q S T R]
time 1032ms: Process F (tau 100ms) started using the CPU for 58ms burst [Q G H I J K L M N O P Q S T R]
time 1090ms: Process F (tau 100ms) completed a CPU burst; 90 bursts to go [Q G H I J K L M N O P Q S T R]
time 1090ms: Recalculating tau for process F: old tau 100ms ==> new tau 60ms [Q G H I J K L M N O P Q S T R]
time 1090ms: Process F switching out of CPU; blocking on I/O until time 1552ms [Q G H I J K L M N O P Q S T R]
time 1094ms: Process G (tau 100ms) started using the CPU for 297ms burst [Q H I J K L M N O P Q S T R]
time 1217ms: Process A (tau 52ms) completed I/O; added to ready queue [Q A H I J K L M N O P Q S T R]
time 1224ms: Process E (tau 12ms) completed I/O; added to ready queue [Q E A H I J K L M N O P Q S T R]
time 1391ms: Process G (tau 100ms) completed a CPU burst; 68 bursts to go [Q E A H I J K L M N O P Q S T R]
time 1391ms: Recalculating tau for process G: old tau 100ms ==> new tau 290ms [Q E A H I J K L M N O P Q S T R]
time 1391ms: Process G switching out of CPU; blocking on I/O until time 1723ms [Q E A H I J K L M N O P Q S T R]
time 1395ms: Process E (tau 12ms) started using the CPU for 3ms burst [Q A H I J K L M N O P Q S T R]
time 1398ms: Process E (tau 12ms) completed a CPU burst; 48 bursts to go [Q A H I J K L M N O P Q S T R]
time 1398ms: Recalculating tau for process E: old tau 12ms ==> new tau 4ms [Q A H I J K L M N O P Q S T R]
time 1398ms: Process E switching out of CPU; blocking on I/O until time 2770ms [Q A H I J K L M N O P Q S T R]
time 1402ms: Process A (tau 52ms) started using the CPU for 274ms burst [Q H I J K L M N O P Q S T R]
time 1552ms: Process F (tau 60ms) completed I/O; added to ready queue [Q F H I J K L M N O P Q S T R]
time 1596ms: Process B (tau 19ms) completed I/O; added to ready queue [Q B F H I J K L M N O P Q S T R]
time 1663ms: Process D (tau 433ms) completed I/O; added to ready queue [Q B F H I J K L M N O P Q S T R D]
time 1676ms: Process A (tau 52ms) completed a CPU burst; 92 bursts to go [Q B F H I J K L M N O P Q S T R D]
time 1676ms: Recalculating tau for process A: old tau 52ms ==> new tau 266ms [Q B F H I J K L M N O P Q S T R D]
time 1676ms: Process A switching out of CPU; blocking on I/O until time 2528ms [Q B F H I J K L M N O P Q S T R D]
time 1680ms: Process B (tau 19ms) started using the CPU for 162ms burst [Q F H I J K L M N O P Q S T R D]
time 1723ms: Process G (tau 290ms) completed I/O; added to ready queue [Q F H I J K L M N O P Q S T G R D]
time 1842ms: Process B (tau 19ms) completed a CPU burst; 49 bursts to go [Q F H I J K L M N O P Q S T G R D]
time 1842ms: Recalculating tau for process B: old tau 19ms ==> new tau 157ms [Q F H I J K L M N O P Q S T G R D]
time 1842ms: Process B switching out of CPU; blocking on I/O until time 3884ms [Q F H I J K L M N O P Q S T G R D]
time 1846ms: Process F (tau 60ms) started using the CPU for 31ms burst [Q H I J K L M N O P Q S T G R D]
time 1877ms: Process F (tau 60ms) completed a CPU burst; 89 bursts to go [Q H I J K L M N O P Q S T G R D]
time 1877ms: Recalculating tau for process F: old tau 60ms ==> new tau 33ms [Q H I J K L M N O P Q S T G R D]
time 1877ms: Process F switching out of CPU; blocking on I/O until time 2129ms [Q H I J K L M N O P Q S T G R D]
time 1881ms: Process H (tau 100ms) started using the CPU for 106ms burst [Q I J K L M N O P Q S T G R D]
time 1987ms: Process H (tau 100ms) completed a CPU burst; 41 bursts to go [Q I J K L M N O P Q S T G R D]
time 1987ms: Recalculating tau for process H: old tau 100ms ==> new tau 106ms [Q I J K L M N O P Q S T G R D]
time 1987ms: Process H switching out of CPU; blocking on I/O until time 2039ms [Q I J K L M N O P Q S T G R D]
time 1991ms: Process I (tau 100ms) started using the CPU for 684ms burst [Q J K L M N O P Q S T G R D]
time 2039ms: Process H (tau 106ms) completed I/O; added to ready queue [Q J K L M N O P Q S T H G R D]
time 2129ms: Process F (tau 33ms) completed I/O; added to ready queue [Q F J K L M N O P Q S T H G R D]
time 2470ms: Process C (tau 64ms) completed I/O; added to ready queue [Q F C J K L M N O P Q S T H G R D]
time 2528ms: Process A (tau 266ms) completed I/O; added to ready queue [Q F C J K L M N O P Q S T H A G R D]
time 2675ms: Process I (tau 100ms) completed a CPU burst; 74 bursts to go [Q F C J K L M N O P Q S T H A G R D]
time 2675ms: Recalculating tau for process I: old tau 100ms ==> new tau 661ms [Q F C J K L M N O P Q S T H A G R D]
time 2675ms: Process I switching out of CPU; blocking on I/O until time 2819ms [Q F C J K L M N O P Q S T H A G R D]
time 2679ms: Process F (tau 33ms) started using the CPU for 71ms burst [Q C J K L M N O P Q S T H A G R D]
time 2750ms: Process F (tau 33ms) completed a CPU burst; 88 bursts to go [Q C J K L M N O P Q S T H A G R D]
time 2750ms: Recalculating tau for process F: old tau 33ms ==> new tau 70ms [Q C J K L M N O P Q S T H A G R D]
time 2750ms: Process F switching out of CPU; blocking on I/O until time 6562ms [Q C J K L M N O P Q S T H A G R D]
time 2754ms: Process C (tau 64ms) started using the CPU for 105ms burst [Q J K L M N O P Q S T H A G R D]
time 2770ms: Process E (tau 4ms) completed I/O; added to ready queue [Q E J K L M N O P Q S T H A G R D]
time 2819ms: Process I (tau 661ms) completed I/O; added to ready queue [Q E J K L M N O P Q S T H A G R D I]
time 2859ms: Process C (tau 64ms) completed a CPU burst; 29 bursts to go [Q E J K L M N O P Q S T H A G R D I]
time 2859ms: Recalculating tau for process C: old tau 64ms ==> new tau 104ms [Q E J K L M N O P Q S T H A G R D I]
time 2859ms: Process C switching out of CPU; blocking on I/O until time 3401ms [Q E J K L M N O P Q S T H A G R D I]
time 2863ms: Process E (tau 4ms) started using the CPU for 285ms burst [Q J K L M N O P Q S T H A G R D I]
time 3148ms: Process E (tau 4ms) completed a CPU burst; 47 bursts to go [Q J K L M N O P Q S T H A G R D I]
time 3148ms: Recalculating tau for process E: old tau 4ms ==> new tau 274ms [Q J K L M N O P Q S T H A G R D I]
time 3148ms: Process E switching out of CPU; blocking on I/O until time 3430ms [Q J K L M N O P Q S T H A G R D I]
time 3152ms: Process J (tau 100ms) started using the CPU for 352ms burst [Q K L M N O P Q S T H A G R D I]
time 3401ms: Process C (tau 104ms) completed I/O; added to ready queue [Q K L M N O P Q S T C H A G R D I]
time 3430ms: Process E (tau 274ms) completed I/O; added to ready queue [Q K L M N O P Q S T C H A E G R D I]
time 3504ms: Process J (tau 100ms) completed a CPU burst; 89 bursts to go [Q K L M N O P Q S T C H A E G R D I]
time 3504ms: Recalculating tau for process J: old tau 100ms ==> new tau 342ms [Q K L M N O P Q S T C H A E G R D I]
time 3504ms: Process J switching out of CPU; blocking on I/O until time 3656ms [Q K L M N O P Q S T C H A E G R D I]
time 3508ms: Process K (tau 100ms) started using the CPU for 56ms burst [Q L M N O P Q S T C H A E G R D I]
time 3564ms: Process K (tau 100ms) completed a CPU burst; 88 bursts to go [Q L M N O P Q S T C H A E G R D I]
time 3564ms: Recalculating tau for process K: old tau 100ms ==> new tau 58ms [Q L M N O P Q S T C H A E G R D I]
time 3564ms: Process K switching out of CPU; blocking on I/O until time 3643ms [Q L M N O P Q S T C H A E G R D I]
time 3568ms: Process L (tau 100ms) started using the CPU for 252ms burst [Q M N O P Q S T C H A E G R D I]
time 3643ms: Process K (tau 58ms) completed I/O; added to ready queue [Q K M N O P Q S T C H A E G R D I]
time 3656ms: Process J (tau 342ms) completed I/O; added to ready queue [Q K M N O P Q S T C H A E G J R D I]
time 3820ms: Process L (tau 100ms) completed a CPU burst; 79 bursts to go [Q K M N O P Q S T C H A E G J R D I]
time 3820ms: Recalculating tau for process L: old tau 100ms ==> new tau 246ms [Q K M N O P Q S T C H A E G J R D I]
time 3820ms: Process L switching out of CPU; blocking on I/O until time 4079ms [Q K M N O P Q S T C H A E G J R D I]
time 3824ms: Process K (tau 58ms) started using the CPU for 28ms burst [Q M N O P Q S T C H A E G J R D I]
time 3852ms: Process K (tau 58ms) completed a CPU burst; 87 bursts to go [Q M N O P Q S T C H A E G J R D I]
time 3852ms: Recalculating tau for process K: old tau 58ms ==> new tau 30ms [Q M N O P Q S T C H A E G J R D I]
time 3852ms: Process K switching out of CPU; blocking on I/O until time 3924ms [Q M N O P Q S T C H A E G J R D I]
time 3856ms: Process M (tau 100ms) started using the CPU for 1160ms burst [Q N O P Q S T C H A E G J R D I]
time 3884ms: Process B (tau 157ms) completed I/O; added to ready queue [Q N O P Q S T C H B A E G J R D I]
time 3924ms: Process K (tau 30ms) completed I/O; added to ready queue [Q K N O P Q S T C H B A E G J R D I]
time 4079ms: Process L (tau 246ms) completed I/O; added to ready queue [Q K N O P Q S T C H B L A E G J R D I]
time 5016ms: Process M (tau 100ms) completed a CPU burst; 17 bursts to go [Q K N O P Q S T C H B L A E G J R D I]
time 5016ms: Recalculating tau for process M: old tau 100ms ==> new tau 1118ms [Q K N O P Q S T C H B L A E G J R D I]
time 5016ms: Process M switching out of CPU; blocking on I/O until time 5300ms [Q K N O P Q S T C H B L A E G J R D I]
time 5020ms: Process K (tau 30ms) started using the CPU for 172ms burst [Q N O P Q S T C H B L A E G J R D I]
time 5192ms: Process K (tau 30ms) completed a CPU burst; 86 bursts to go [Q N O P Q S T C H B L A E G J R D I]
time 5192ms: Recalculating tau for process K: old tau 30ms ==> new tau 167ms [Q N O P Q S T C H B L A E G J R D I]
time 5192ms: Process K switching out of CPU; blocking on I/O until time 5264ms [Q N O P Q S T C H B L A E G J R D I]
time 5196ms: Process N (tau 100ms) started using the CPU for 20ms burst [Q O P Q S T C H B L A E G J R D I]
time 5216ms: Process N (tau 100ms) completed a CPU burst; 17 bursts to go [Q O P Q S T C H B L A E G J R D I]
time 5216ms: Recalculating tau for process N: old tau 100ms ==> new tau 24ms [Q O P Q S T C H B L A E G J R D I]
time 5216ms: Process N switching out of CPU; blocking on I/O until time 5370ms [Q O P Q S T C H B L A E G J R D I]
time 5220ms: Process O (tau 100ms) started using the CPU for 200ms burst [Q P Q S T C H B L A E G J R D I]
time 5264ms: Process K (tau 167ms) completed I/O; added to ready queue [Q P Q S T C H B K L A E G J R D I]
time 5300ms: Process M (tau 1118ms) completed I/O; added to ready queue [Q P Q S T C H B K L A E G J R D I M]
time 5370ms: Process N (tau 24ms) completed I/O; added to ready queue [Q N P Q S T C H B K L A E G J R D I M]
time 5420ms: Process O (tau 100ms) completed a CPU burst; 2 bursts to go [Q N P Q S T C H B K L A E G J R D I M]
time 5420ms: Recalculating tau for process O: old tau 100ms ==> new tau 196ms [Q N P Q S T C H B K L A E G J R D I M]
time 5420ms: Process O switching out of CPU; blocking on I/O until time 5614ms [Q N P Q S T C H B K L A E G J R D I M]
time 5424ms: Process N (tau 24ms) started using the CPU for 372ms burst [Q P Q S T C H B K L A E G J R D I M]
time 5614ms: Process O (tau 196ms) completed I/O; added to ready queue [Q P Q S T C H B K O L A E G J R D I M]
time 5796ms: Process N (tau 24ms) completed a CPU burst; 16 bursts to go [Q P Q S T C H B K O L A E G J R D I M]
time 5796ms: Recalculating tau for process N: old tau 24ms ==> new tau 359ms [Q P Q S T C H B K O L A E G J R D I M]
time 5796ms: Process N switching out of CPU; blocking on I/O until time 6198ms [Q P Q S T C H B K O L A E G J R D I M]
time 5800ms: Process P (tau 100ms) started using the CPU for 72ms burst [Q Q S T C H B K O L A E G J R D I M]
time 5872ms: Process P (tau 100ms) completed a CPU burst; 74 bursts to go [Q Q S T C H B K O L A E G J R D I M]
time 5872ms: Recalculating tau for process P: old tau 100ms ==> new tau 74ms [Q Q S T C H B K O L A E G J R D I M]
time 5872ms: Process P switching out of CPU; blocking on I/O until time 5881ms [Q Q S T C H B K O L A E G J R D I M]
time 5876ms: Process Q (tau 100ms) started using the CPU for 88ms burst [Q S T C H B K O L A E G J R D I M]
time 5881ms: Process P (tau 74ms) completed I/O; added to ready queue [Q P S T C H B K O L A E G J R D I M]
time 5964ms: Process Q (tau 100ms) completed a CPU burst; 58 bursts to go [Q P S T C H B K O L A E G J R D I M]
time 5964ms: Recalculating tau for process Q: old tau 100ms ==> new tau 89ms [Q P S T C H B K O L A E G J R D I M]
time 5964ms: Process Q switching out of CPU; blocking on I/O until time 6273ms [Q P S T C H B K O L A E G J R D I M]
time 5968ms: Process P (tau 74ms) started using the CPU for 32ms burst [Q S T C H B K O L A E G J R D I M]
time 6000ms: Process P (tau 74ms) completed a CPU burst; 73 bursts to go [Q S T C H B K O L A E G J R D I M]
time 6000ms: Recalculating tau for process P: old tau 74ms ==> new tau 34ms [Q S T C H B K O L A E G J R D I M]
time 6000ms: Process P switching out of CPU; blocking on I/O until time 6322ms [Q S T C H B K O L A E G J R D I M]
time 6004ms: Process S (tau 100ms) started using the CPU for 840ms burst [Q T C H B K O L A E G J R D I M]
time 6198ms: Process N (tau 359ms) completed I/O; added to ready queue [Q T C H B K O L A E G J R N D I M]
time 6273ms: Process Q (tau 89ms) completed I/O; added to ready queue [Q Q T C H B K O L A E G J R N D I M]
time 6322ms: Process P (tau 34ms) completed I/O; added to ready queue [Q P Q T C H B K O L A E G J R N D I M]
time 6562ms: Process F (tau 70ms) completed I/O; added to ready queue [Q P F Q T C H B K O L A E G J R N D I M]
time 6844ms: Process S (tau 100ms) completed a CPU burst; 39 bursts to go [Q P F Q T C H B K O L A E G J R N D I M]
time 6844ms: Recalculating tau for process S: old tau 100ms ==> new tau 811ms [Q P F Q T C H B K O L A E G J R N D I M]
time 6844ms: Process S switching out of CPU; blocking on I/O until time 7116ms [Q P F Q T C H B K O L A E G J R N D I M]
time 6848ms: Process P (tau 34ms) started using the CPU for 268ms burst [Q F Q T C H B K O L A E G J R N D I M]
time 7116ms: Process S (tau 811ms) completed I/O; added to ready queue [Q F Q T C H B K O L A E G J R N D I S M]
time 7116ms: Process P (tau 34ms) completed a CPU burst; 72 bursts to go [Q F Q T C H B K O L A E G J R N D I S M]
time 7116ms: Recalculating tau for process P: old tau 34ms ==> new tau 259ms [Q F Q T C H B K O L A E G J R N D I S M]
time 7116ms: Process P switching out of CPU; blocking on I/O until time 7318ms [Q F Q T C H B K O L A E G J R N D I S M]
time 7120ms: Process F (tau 70ms) started using the CPU for 20ms burst [Q Q T C H B K O L A E G J R N D I S M]
time 7140ms: Process F (tau 70ms) completed a CPU burst; 87 bursts to go [Q Q T C H B K O L A E G J R N D I S M]
time 7140ms: Recalculating tau for process F: old tau 70ms ==> new tau 22ms [Q Q T C H B K O L A E G J R N D I S M]
time 7140ms: Process F switching out of CPU; blocking on I/O until time 7192ms [Q Q T C H B K O L A E G J R N D I S M]
time 7144ms: Process Q (tau 89ms) started using the CPU for 268ms burst [Q T C H B K O L A E G J R N D I S M]
time 7192ms: Process F (tau 22ms) completed I/O; added to ready queue [Q F T C H B K O L A E G J R N D I S M]
time 7318ms: Process P (tau 259ms) completed I/O; added to ready queue [Q F T C H B K O L P A E G J R N D I S M]
time 7412ms: Process Q (tau 89ms) completed a CPU burst; 57 bursts to go [Q F T C H B K O L P A E G J R N D I S M]
time 7412ms: Recalculating tau for process Q: old tau 89ms ==> new tau 261ms [Q F T C H B K O L P A E G J R N D I S M]
time 7412ms: Process Q switching out of CPU; blocking on I/O until time 7429ms [Q F T C H B K O L P A E G J R N D I S M]
time 7416ms: Process F (tau 22ms) started using the CPU for 3ms burst [Q T C H B K O L P A E G J R N D I S M]
time 7419ms: Process F (tau 22ms) completed a CPU burst; 86 bursts to go [Q T C H B K O L P A E G J R N D I S M]
time 7419ms: Recalculating tau for process F: old tau 22ms ==> new tau 4ms [Q T C H B K O L P A E G J R N D I S M]
time 7419ms: Process F switching out of CPU; blocking on I/O until time 11121ms [Q T C H B K O L P A E G J R N D I S M]
time 7423ms: Process T (tau 100ms) started using the CPU for 464ms burst [Q C H B K O L P A E G J R N D I S M]
time 7429ms: Process Q (tau 261ms) completed I/O; added to ready queue [Q C H B K O L P Q A E G J R N D I S M]
time 7887ms: Process T (tau 100ms) completed a CPU burst; 98 bursts to go [Q C H B K O L P Q A E G J R N D I S M]
time 7887ms: Recalculating tau for process T: old tau 100ms ==> new tau 450ms [Q C H B K O L P Q A E G J R N D I S M]
time 7887ms: Process T switching out of CPU; blocking on I/O until time 8196ms [Q C H B K O L P Q A E G J R N D I S M]
time 7891ms: Process C (tau 104ms) started using the CPU for 44ms burst [Q H B K O L P Q A E G J R N D I S M]
time 7935ms: Process C (tau 104ms) completed a CPU burst; 28 bursts to go [Q H B K O L P Q A E G J R N D I S M]
time 7935ms: Recalculating tau for process C: old tau 104ms ==> new tau 47ms [Q H B K O L P Q A E G J R N D I S M]
time 7935ms: Process C switching out of CPU; blocking on I/O until time 8317ms [Q H B K O L P Q A E G J R N D I S M]
time 7939ms: Process H (tau 106ms) started using the CPU for 62ms burst [Q B K O L P Q A E G J R N D I S M]
time 8001ms: Process H (tau 106ms) completed a CPU burst; 40 bursts to go [Q B K O L P Q A E G J R N D I S M]
time 8001ms: Recalculating tau for process H: old tau 106ms ==> new tau 64ms [Q B K O L P Q A E G J R N D I S M]
time 8001ms: Process H switching out of CPU; blocking on I/O until time 12003ms [Q B K O L P Q A E G J R N D I S M]
time 8005ms: Process B (tau 157ms) started using the CPU for 101ms burst [Q K O L P Q A E G J R N D I S M]
time 8106ms: Process B (tau 157ms) completed a CPU burst; 48 bursts to go [Q K O L P Q A E G J R N D I S M]
time 8106ms: Recalculating tau for process B: old tau 157ms ==> new tau 104ms [Q K O L P Q A E G J R N D I S M]
time 8106ms: Process B switching out of CPU; blocking on I/O until time 8358ms [Q K O L P Q A E G J R N D I S M]
time 8110ms: Process K (tau 167ms) started using the CPU for 1100ms burst [Q O L P Q A E G J R N D I S M]
time 8196ms: Process T (tau 450ms) completed I/O; added to ready queue [Q O L P Q A E G J R N D T I S M]
time 8317ms: Process C (tau 47ms) completed I/O; added to ready queue [Q C O L P Q A E G J R N D T I S M]
time 8358ms: Process B (tau 104ms) completed I/O; added to ready queue [Q C B O L P Q A E G J R N D T I S M]
time 9210ms: Process K (tau 167ms) completed a CPU burst; 85 bursts to go [Q C B O L P Q A E G J R N D T I S M]
time 9210ms: Recalculating tau for process K: old tau 167ms ==> new tau 1063ms [Q C B O L P Q A E G J R N D T I S M]
time 9210ms: Process K switching out of CPU; blocking on I/O until time 9449ms [Q C B O L P Q A E G J R N D T I S M]
time 9214ms: Process C (tau 47ms) started using the CPU for 85ms burst [Q B O L P Q A E G J R N D T I S M]
time 9299ms: Process C (tau 47ms) completed a CPU burst; 27 bursts to go [Q B O L P Q A E G J R N D T I S M]
time 9299ms: Recalculating tau for process C: old tau 47ms ==> new tau 84ms [Q B O L P Q A E G J R N D T I S M]
time 9299ms: Process C switching out of CPU; blocking on I/O until time 9951ms [Q B O L P Q A E G J R N D T I S M]
time 9303ms: Process B (tau 104ms) started using the CPU for 426ms burst [Q O L P Q A E G J R N D T I S M]
time 9449ms: Process K (tau 1063ms) completed I/O; added to ready queue [Q O L P Q A E G J R N D T I S K M]
time 9729ms: Process B (tau 104ms) completed a CPU burst; 47 bursts to go [Q O L P Q A E G J R N D T I S K M]
time 9729ms: Recalculating tau for process B: old tau 104ms ==> new tau 414ms [Q O L P Q A E G J R N D T I S K M]
time 9729ms: Process B switching out of CPU; blocking on I/O until time 10231ms [Q O L P Q A E G J R N D T I S K M]
time 9733ms: Process O (tau 196ms) started using the CPU for 4ms burst [Q L P Q A E G J R N D T I S K M]
time 9737ms: Process O (tau 196ms) completed a CPU burst; 1 bursts to go [Q L P Q A E G J R N D T I S K M]
time 9737ms: Recalculating tau for process O: old tau 196ms ==> new tau 12ms [Q L P Q A E G J R N D T I S K M]
time 9737ms: Process O switching out of CPU; blocking on I/O until time 9979ms [Q L P Q A E G J R N D T I S K M]
time 9741ms: Process L (tau 246ms) started using the CPU for 720ms burst [Q P Q A E G J R N D T I S K M]
time 9951ms: Process C (tau 84ms) completed I/O; added to ready queue [Q C P Q A E G J R N D T I S K M]
time 9979ms: Process O (tau 12ms) completed I/O; added to ready queue [Q O C P Q A E G J R N D T I S K M]
time 10761ms: Process O terminated [Q C P Q A E G J R N B D T I L S K M]
time 59378ms: Process C terminated [Q F T N I K M S R Q L J P]
time 77538ms: Process H terminated [Q A F T I D K M S R Q N L J P]
time 88677ms: Process E terminated [Q D F K S M R T I Q N L J P]
time 91615ms: Process B terminated [Q G D F S M R T I Q N L J P]
time 109822ms: Process G terminated [Q F A D M T S I R Q N L K J P]
time 143261ms: Process F terminated [Q R S Q N I L T K J M P]
time 154090ms: Process S terminated [Q Q N I L T K J M P]
time 160945ms: Process N terminated [Q Q L T K R J M P]
time 173331ms: Process A terminated [Q Q K I T R J M P]
time 178503ms: Process D terminated [Q K Q T L R J M P]
time 214175ms: Process Q terminated [Q T K R I J M L P]
time 263351ms: Process T terminated [Q R K M L P]
time 272151ms: Process I terminated [Q K R M L P]
time 283923ms: Process M terminated [Q K J R P]
time 314087ms: Process K terminated [Q J L P]
time 323655ms: Process R terminated [Q J P]
time 344318ms: Process L terminated [Q <empty>]
time 361339ms: Process J terminated [Q P]
time 378637ms: Process P terminated [Q <empty>]
time 378639ms: Simulator ended for SJF [Q <empty>]

time 0ms: Simulator started for SRT [Q <empty>]
time 2ms: Process E (tau 100ms) arrived; added to ready queue [Q E]
time 4ms: Process E (tau 100ms) started using the CPU for 8ms burst [Q <empty>]
time 7ms: Process R (tau 100ms) arrived; added to ready queue [Q R]
time 12ms: Process E (tau 100ms) completed a CPU burst; 49 bursts to go [Q R]
time 12ms: Recalculating tau for process E: old tau 100ms ==> new tau 12ms [Q R]
time 12ms: Process E switching out of CPU; blocking on I/O until time 1224ms [Q R]
time 16ms: Process R (tau 100ms) started using the CPU for 356ms burst [Q <empty>]
time 33ms: Process G (tau 100ms) arrived; added to ready queue [Q G]
time 41ms: Process D (tau 100ms) arrived; added to ready queue [Q D G]
time 45ms: Process A (tau 100ms) arrived; added to ready queue [Q A D G]
time 53ms: Process K (tau 100ms) arrived; added to ready queue [Q A D G K]
time 53ms: Process T (tau 100ms) arrived; added to ready queue [Q A D G K T]
time 67ms: Process I (tau 100ms) arrived; added to ready queue [Q A D G I K T]
time 73ms: Process J (tau 100ms) arrived; added to ready queue [Q A D G I J K T]
time 80ms: Process L (tau 100ms) arrived; added to ready queue [Q A D G I J K L T]
time 80ms: Process N (tau 100ms) arrived; added to ready queue [Q A D G I J K L N T]
time 88ms: Process H (tau 100ms) arrived; added to ready queue [Q A D G H I J K L N T]
time 99ms: Process Q (tau 100ms) arrived; added to ready queue [Q A D G H I J K L N Q T]
time 109ms: Process P (tau 100ms) arrived; added to ready queue [Q A D G H I J K L N P Q T]
time 119ms: Process F (tau 100ms) arrived; added to ready queue [Q A D F G H I J K L N P Q T]
time 131ms: Process O (tau 100ms) arrived; added to ready queue [Q A D F G H I J K L N O P Q T]
time 142ms: Process C (tau 100ms) arrived; added to ready queue [Q A C D F G H I J K L N O P Q T]
time 165ms: Process S (tau 100ms) arrived; added to ready queue [Q A C D F G H I J K L N O P Q S T]
time 178ms: Process M (tau 100ms) arrived; added to ready queue [Q A C D F G H I J K L M N O P Q S T]
time 190ms: Process B (tau 100ms) arrived; added to ready queue [Q A B C D F G H I J K L M N O P Q S T]
time 372ms: Process R (tau 100ms) completed a CPU burst; 98 bursts to go [Q A B C D F G H I J K L M N O P Q S T]
time 372ms: Recalculating tau for process R: old tau 100ms ==> new tau 346ms [Q A B C D F G H I J K L M N O P Q S T]
time 372ms: Process R switching out of CPU; blocking on I/O until time 474ms [Q A B C D F G H I J K L M N O P Q S T]
time 376ms: Process A (tau 100ms) started using the CPU for 49ms burst [Q B C D F G H I J K L M N O P Q S T]
time 425ms: Process A (tau 100ms) completed a CPU burst; 93 bursts to go [Q B C D F G H I J K L M N O P Q S T]
time 425ms: Recalculating tau for process A: old tau 100ms ==> new tau 52ms [Q B C D F G H I J K L M N O P Q S T]
time 425ms: Process A switching out of CPU; blocking on I/O until time 1217ms [Q B C D F G H I J K L M N O P Q S T]
time 429ms: Process B (tau 100ms) started using the CPU for 15ms burst [Q C D F G H I J K L M N O P Q S T]
time 444ms: Process B (tau 100ms) completed a CPU burst; 50 bursts to go [Q C D F G H I J K L M N O P Q S T]
time 444ms: Recalculating tau for process B: old tau 100ms ==> new tau 19ms [Q C D F G H I J K L M N O P Q S T]
time 444ms: Process B switching out of CPU; blocking on I/O until time 1596ms [Q C D F G H I J K L M N O P Q S T]
time 448ms: Process C (tau 100ms) started using the CPU for 63ms burst [Q D F G H I J K L M N O P Q S T]
time 474ms: Process R (tau 346ms) completed I/O; added to ready queue [Q D F G H I J K L M N O P Q S T R]
time 511ms: Process C (tau 100ms) completed a CPU burst; 31 bursts to go [Q D F G H I J K L M N O P Q S T R]
time 511ms: Recalculating tau for process C: old tau 100ms ==> new tau 65ms [Q D F G H I J K L M N O P Q S T R]
time 511ms: Process C switching out of CPU; blocking on I/O until time 613ms [Q D F G H I J K L M N O P Q S T R]
time 515ms: Process D (tau 100ms) started using the CPU for 446ms burst [Q F G H I J K L M N O P Q S T R]
time 613ms: Process C (tau 65ms) completed I/O; added to ready queue [Q C F G H I J K L M N O P Q S T R]
time 961ms: Process D (tau 100ms) completed a CPU burst; 84 bursts to go [Q C F G H I J K L M N O P Q S T R]
time 961ms: Recalculating tau for process D: old tau 100ms ==> new tau 433ms [Q C F G H I J K L M N O P Q S T R]
time 961ms: Process D switching out of CPU; blocking on I/O until time 1663ms [Q C F G H I J K L M N O P Q S T R]
time 965ms: Process C (tau 65ms) started using the CPU for 63ms burst [Q F G H I J K L M N O P Q S T R]
time 1028ms: Process C (tau 65ms) completed a CPU burst; 30 bursts to go [Q F G H I J K L M N O P Q S T R]
time 1028ms: Recalculating tau for process C: old tau 65ms ==> new tau 64ms [Q F G H I J K L M N O P Q S T R]
time 1028ms: Process C switching out of CPU; blocking on I/O until time 2470ms [Q F G H I J K L M N O P Q S T R]
time 1032ms: Process F (tau 100ms) started using the CPU for 58ms burst [Q G H I J K L M N O P Q S T R]
time 1090ms: Process F (tau 100ms) completed a CPU burst; 90 bursts to go [Q G H I J K L M N O P Q S T R]
time 1090ms: Recalculating tau for process F: old tau 100ms ==> new tau 60ms [Q G H I J K L M N O P Q S T R]
time 1090ms: Process F switching out of CPU; blocking on I/O until time 1552ms [Q G H I J K L M N O P Q S T R]
time 1094ms: Process G (tau 100ms) started using the CPU for 297ms burst [Q H I J K L M N O P Q S T R]
time 1217ms: Process A (tau 52ms) completed I/O; added to ready queue [Q A H I J K L M N O P Q S T R]
time 1224ms: Process E (tau 12ms) completed I/O; added to ready queue [Q E A H I J K L M N O P Q S T R]
time 1391ms: Process G (tau 100ms) completed a CPU burst; 68 bursts to go [Q E A H I J K L M N O P Q S T R]
time 1391ms: Recalculating tau for process G: old tau 100ms ==> new tau 290ms [Q E A H I J K L M N O P Q S T R]
time 1391ms: Process G switching out of CPU; blocking on I/O until time 1723ms [Q E A H I J K L M N O P Q S T R]
time 1395ms: Process E (tau 12ms) started using the CPU for 3ms burst [Q A H I J K L M N O P Q S T R]
time 1398ms: Process E (tau 12ms) completed a CPU burst; 48 bursts to go [Q A H I J K L M N O P Q S T R]
time 1398ms: Recalculating tau for process E: old tau 12ms ==> new tau 4ms [Q A H I J K L M N O P Q S T R]
time 1398ms: Process E switching out of CPU; blocking on I/O until time 2770ms [Q A H I J K L M N O P Q S T R]
time 1402ms: Process A (tau 52ms) started using the CPU for 274ms burst [Q H I J K L M N O P Q S T R]
time 1552ms: Process F (tau 60ms) completed I/O; added to ready queue [Q F H I J K L M N O P Q S T R]
time 1596ms: Process B (tau 19ms) completed I/O; added to ready queue [Q B F H I J K L M N O P Q S T R]
time 1663ms: Process D (tau 433ms) completed I/O; added to ready queue [Q B F H I J K L M N O P Q S T R D]
time 1676ms: Process A (tau 52ms) completed a CPU burst; 92 bursts to go [Q B F H I J K L M N O P Q S T R D]
time 1676ms: Recalculating tau for process A: old tau 52ms ==> new tau 266ms [Q B F H I J K L M N O P Q S T R D]
time 1676ms: Process A switching out of CPU; blocking on I/O until time 2528ms [Q B F H I J K L M N O P Q S T R D]
time 1680ms: Process B (tau 19ms) started using the CPU for 162ms burst [Q F H I J K L M N O P Q S T R D]
time 1723ms: Process G (tau 290ms) completed I/O; added to ready queue [Q F H I J K L M N O P Q S T G R D]
time 1842ms: Process B (tau 19ms) completed a CPU burst; 49 bursts to go [Q F H I J K L M N O P Q S T G R D]
time 1842ms: Recalculating tau for process B: old tau 19ms ==> new tau 157ms [Q F H I J K L M N O P Q S T G R D]
time 1842ms: Process B switching out of CPU; blocking on I/O until time 3884ms [Q F H I J K L M N O P Q S T G R D]
time 1846ms: Process F (tau 60ms) started using the CPU for 31ms burst [Q H I J K L M N O P Q S T G R D]
time 1877ms: Process F (tau 60ms) completed a CPU burst; 89 bursts to go [Q H I J K L M N O P Q S T G R D]
time 1877ms: Recalculating tau for process F: old tau 60ms ==> new tau 33ms [Q H I J K L M N O P Q S T G R D]
time 1877ms: Process F switching out of CPU; blocking on I/O until time 2129ms [Q H I J K L M N O P Q S T G R D]
time 1881ms: Process H (tau 100ms) started using the CPU for 106ms burst [Q I J K L M N O P Q S T G R D]
time 1987ms: Process H (tau 100ms) completed a CPU burst; 41 bursts to go [Q I J K L M N O P Q S T G R D]
time 1987ms: Recalculating tau for process H: old tau 100ms ==> new tau 106ms [Q I J K L M N O P Q S T G R D]
time 1987ms: Process H switching out of CPU; blocking on I/O until time 2039ms [Q I J K L M N O P Q S T G R D]
time 1991ms: Process I (tau 100ms) started using the CPU for 684ms burst [Q J K L M N O P Q S T G R D]
time 2039ms: Process H (tau 106ms) completed I/O; added to ready queue [Q J K L M N O P Q S T H G R D]
time 2129ms: Process F (tau 33ms) completed I/O; added to ready queue [Q F J K L M N O P Q S T H G R D]
time 2470ms: Process C (tau 64ms) completed I/O; added to ready queue [Q F C J K L M N O P Q S T H G R D]
time 2528ms: Process A (tau 266ms) completed I/O; added to ready queue [Q F C J K L M N O P Q S T H A G R D]
time 2675ms: Process I (tau 100ms) completed a CPU burst; 74 bursts to go [Q F C J K L M N O P Q S T H A G R D]
time 2675ms: Recalculating tau for process I: old tau 100ms ==> new tau 661ms [Q F C J K L M N O P Q S T H A G R D]
time 2675ms: Process I switching out of CPU; blocking on I/O until time 2819ms [Q F C J K L M N O P Q S T H A G R D]
time 2679ms: Process F (tau 33ms) started using the CPU for 71ms burst [Q C J K L M N O P Q S T H A G R D]
time 2750ms: Process F (tau 33ms) completed a CPU burst; 88 bursts to go [Q C J K L M N O P Q S T H A G R D]
time 2750ms: Recalculating tau for process F: old tau 33ms ==> new tau 70ms [Q C J K L M N O P Q S T H A G R D]
time 2750ms: Process F switching out of CPU; blocking on I/O until time 6562ms [Q C J K L M N O P Q S T H A G R D]
time 2754ms: Process C (tau 64ms) started using the CPU for 105ms burst [Q J K L M N O P Q S T H A G R D]
time 2770ms: Process E (tau 4ms) completed I/O; preempting C [Q J K L M N O P Q S T H A G R D]
time 2774ms: Process E (tau 4ms) started using the CPU for 285ms burst [Q C J K L M N O P Q S T H A G R D]
time 2819ms: Process I (tau 661ms) completed I/O; added to ready queue [Q C J K L M N O P Q S T H A G R D I]
time 3059ms: Process E (tau 4ms) completed a CPU burst; 47 bursts to go [Q C J K L M N O P Q S T H A G R D I]
time 3059ms: Recalculating tau for process E: old tau 4ms ==> new tau 274ms [Q C J K L M N O P Q S T H A G R D I]
time 3059ms: Process E switching out of CPU; blocking on I/O until time 3341ms [Q C J K L M N O P Q S T H A G R D I]
time 3063ms: Process C (tau 48ms) started using the CPU for 89ms burst [Q J K L M N O P Q S T H A G R D I]
time 3152ms: Process C (tau 64ms) completed a CPU burst; 29 bursts to go [Q J K L M N O P Q S T H A G R D I]
time 3152ms: Recalculating tau for process C: old tau 64ms ==> new tau 104ms [Q J K L M N O P Q S T H A G R D I]
time 3152ms: Process C switching out of CPU; blocking on I/O until time 3694ms [Q J K L M N O P Q S T H A G R D I]
time 3156ms: Process J (tau 100ms) started using the CPU for 352ms burst [Q K L M N O P Q S T H A G R D I]
time 3341ms: Process E (tau 274ms) completed I/O; added to ready queue [Q K L M N O P Q S T H A E G R D I]
time 3508ms: Process J (tau 100ms) completed a CPU burst; 89 bursts to go [Q K L M N O P Q S T H A E G R D I]
time 3508ms: Recalculating tau for process J: old tau 100ms ==> new tau 342ms [Q K L M N O P Q S T H A E G R D I]
time 3508ms: Process J switching out of CPU; blocking on I/O until time 3660ms [Q K L M N O P Q S T H A E G R D I]
time 3512ms: Process K (tau 100ms) started using the CPU for 56ms burst [Q L M N O P Q S T H A E G R D I]
time 3568ms: Process K (tau 100ms) completed a CPU burst; 88 bursts to go [Q L M N O P Q S T H A E G R D I]
time 3568ms: Recalculating tau for process K: old tau 100ms ==> new tau 58ms [Q L M N O P Q S T H A E G R D I]
time 3568ms: Process K switching out of CPU; blocking on I/O until time 3647ms [Q L M N O P Q S T H A E G R D I]
time 3572ms: Process L (tau 100ms) started using the CPU for 252ms burst [Q M N O P Q S T H A E G R D I]
time 3647ms: Process K (tau 58ms) completed I/O; added to ready queue [Q K M N O P Q S T H A E G R D I]
time 3660ms: Process J (tau 342ms) completed I/O; added to ready queue [Q K M N O P Q S T H A E G J R D I]
time 3694ms: Process C (tau 104ms) completed I/O; added to ready queue [Q K M N O P Q S T C H A E G J R D I]
time 3824ms: Process L (tau 100ms) completed a CPU burst; 79 bursts to go [Q K M N O P Q S T C H A E G J R D I]
time 3824ms: Recalculating tau for process L: old tau 100ms ==> new tau 246ms [Q K M N O P Q S T C H A E G J R D I]
time 3824ms: Process L switching out of CPU; blocking on I/O until time 4083ms [Q K M N O P Q S T C H A E G J R D I]
time 3828ms: Process K (tau 58ms) started using the CPU for 28ms burst [Q M N O P Q S T C H A E G J R D I]
time 3856ms: Process K (tau 58ms) completed a CPU burst; 87 bursts to go [Q M N O P Q S T C H A E G J R D I]
time 3856ms: Recalculating tau for process K: old tau 58ms ==> new tau 30ms [Q M N O P Q S T C H A E G J R D I]
time 3856ms: Process K switching out of CPU; blocking on I/O until time 3928ms [Q M N O P Q S T C H A E G J R D I]
time 3860ms: Process M (tau 100ms) started using the CPU for 1160ms burst [Q N O P Q S T C H A E G J R D I]
time 3884ms: Process B (tau 157ms) completed I/O; added to ready queue [Q N O P Q S T C H B A E G J R D I]
time 3928ms: Process K (tau 30ms) completed I/O; preempting M [Q N O P Q S T C H B A E G J R D I]
time 3928ms: Process K (tau 30ms) completed I/O; added to ready queue [Q K N O P Q S T C H B A E G J R D I]
time 4083ms: Process L (tau 246ms) completed I/O; added to ready queue [Q K N O P Q S T C H B L A E G J R D I]
time 5020ms: Process M (tau 100ms) completed a CPU burst; 17 bursts to go [Q K N O P Q S T C H B L A E G J R D I]
time 5020ms: Recalculating tau for process M: old tau 100ms ==> new tau 1118ms [Q K N O P Q S T C H B L A E G J R D I]
time 5020ms: Process M switching out of CPU; blocking on I/O until time 5304ms [Q K N O P Q S T C H B L A E G J R D I]
time 5024ms: Process K (tau 30ms) started using the CPU for 172ms burst [Q N O P Q S T C H B L A E G J R D I]
time 5196ms: Process K (tau 30ms) completed a CPU burst; 86 bursts to go [Q N O P Q S T C H B L A E G J R D I]
time 5196ms: Recalculating tau for process K: old tau 30ms ==> new tau 167ms [Q N O P Q S T C H B L A E G J R D I]
time 5196ms: Process K switching out of CPU; blocking on I/O until time 5268ms [Q N O P Q S T C H B L A E G J R D I]
time 5200ms: Process N (tau 100ms) started using the CPU for 20ms burst [Q O P Q S T C H B L A E G J R D I]
time 5220ms: Process N (tau 100ms) completed a CPU burst; 17 bursts to go [Q O P Q S T C H B L A E G J R D I]
time 5220ms: Recalculating tau for process N: old tau 100ms ==> new tau 24ms [Q O P Q S T C H B L A E G J R D I]
time 5220ms: Process N switching out of CPU; blocking on I/O until time 5374ms [Q O P Q S T C H B L A E G J R D I]
time 5224ms: Process O (tau 100ms) started using the CPU for 200ms burst [Q P Q S T C H B L A E G J R D I]
time 5268ms: Process K (tau 167ms) completed I/O; added to ready queue [Q P Q S T C H B K L A E G J R D I]
time 5304ms: Process M (tau 1118ms) completed I/O; added to ready queue [Q P Q S T C H B K L A E G J R D I M]
time 5374ms: Process N (tau 24ms) completed I/O; added to ready queue [Q N P Q S T C H B K L A E G J R D I M]
time 5424ms: Process O (tau 100ms) completed a CPU burst; 2 bursts to go [Q N P Q S T C H B K L A E G J R D I M]
time 5424ms: Recalculating tau for process O: old tau 100ms ==> new tau 196ms [Q N P Q S T C H B K L A E G J R D I M]
time 5424ms: Process O switching out of CPU; blocking on I/O until time 5618ms [Q N P Q S T C H B K L A E G J R D I M]
time 5428ms: Process N (tau 24ms) started using the CPU for 372ms burst [Q P Q S T C H B K L A E G J R D I M]
time 5618ms: Process O (tau 196ms) completed I/O; added to ready queue [Q P Q S T C H B K O L A E G J R D I M]
time 5800ms: Process N (tau 24ms) completed a CPU burst; 16 bursts to go [Q P Q S T C H B K O L A E G J R D I M]
time 5800ms: Recalculating tau for process N: old tau 24ms ==> new tau 359ms [Q P Q S T C H B K O L A E G J R D I M]
time 5800ms: Process N switching out of CPU; blocking on I/O until time 6202ms [Q P Q S T C H B K O L A E G J R D I M]
time 5804ms: Process P (tau 100ms) started using the CPU for 72ms burst [Q Q S T C H B K O L A E G J R D I M]
time 5876ms: Process P (tau 100ms) completed a CPU burst; 74 bursts to go [Q Q S T C H B K O L A E G J R D I M]
time 5876ms: Recalculating tau for process P: old tau 100ms ==> new tau 74ms [Q Q S T C H B K O L A E G J R D I M]
time 5876ms: Process P switching out of CPU; blocking on I/O until time 5885ms [Q Q S T C H B K O L A E G J R D I M]
time 5880ms: Process Q (tau 100ms) started using the CPU for 88ms burst [Q S T C H B K O L A E G J R D I M]
time 5885ms: Process P (tau 74ms) completed I/O; preempting Q [Q S T C H B K O L A E G J R D I M]
time 5889ms: Process P (tau 74ms) started using the CPU for 32ms burst [Q Q S T C H B K O L A E G J R D I M]
time 5921ms: Process P (tau 74ms) completed a CPU burst; 73 bursts to go [Q Q S T C H B K O L A E G J R D I M]
time 5921ms: Recalculating tau for process P: old tau 74ms ==> new tau 34ms [Q Q S T C H B K O L A E G J R D I M]
time 5921ms: Process P switching out of CPU; blocking on I/O until time 6243ms [Q Q S T C H B K O L A E G J R D I M]
time 5925ms: Process Q (tau 95ms) started using the CPU for 83ms burst [Q S T C H B K O L A E G J R D I M]
time 6008ms: Process Q (tau 100ms) completed a CPU burst; 58 bursts to go [Q S T C H B K O L A E G J R D I M]
time 6008ms: Recalculating tau for process Q: old tau 100ms ==> new tau 89ms [Q S T C H B K O L A E G J R D I M]
time 6008ms: Process Q switching out of CPU; blocking on I/O until time 6317ms [Q S T C H B K O L A E G J R D I M]
time 6012ms: Process S (tau 100ms) started using the CPU for 840ms burst [Q T C H B K O L A E G J R D I M]
time 6202ms: Process N (tau 359ms) completed I/O; added to ready queue [Q T C H B K O L A E G J R N D I M]
time 6243ms: Process P (tau 34ms) completed I/O; added to ready queue [Q P T C H B K O L A E G J R N D I M]
time 6317ms: Process Q (tau 89ms) completed I/O; added to ready queue [Q P Q T C H B K O L A E G J R N D I M]
time 6562ms: Process F (tau 70ms) completed I/O; added to ready queue [Q P F Q T C H B K O L A E G J R N D I M]
time 6852ms: Process S (tau 100ms) completed a CPU burst; 39 bursts to go [Q P F Q T C H B K O L A E G J R N D I M]
time 6852ms: Recalculating tau for process S: old tau 100ms ==> new tau 811ms [Q P F Q T C H B K O L A E G J R N D I M]
time 6852ms: Process S switching out of CPU; blocking on I/O until time 7124ms [Q P F Q T C H B K O L A E G J R N D I M]
time 6856ms: Process P (tau 34ms) started using the CPU for 268ms burst [Q F Q T C H B K O L A E G J R N D I M]
time 7124ms: Process P (tau 34ms) completed a CPU burst; 72 bursts to go [Q F Q T C H B K O L A E G J R N D I M]
time 7124ms: Recalculating tau for process P: old tau 34ms ==> new tau 259ms [Q F Q T C H B K O L A E G J R N D I M]
time 7124ms: Process P switching out of CPU; blocking on I/O until time 7326ms [Q F Q T C H B K O L A E G J R N D I M]
time 7128ms: Process F (tau 70ms) started using the CPU for 20ms burst [Q Q T C H B K O L A E G J R N D I M]
time 7124ms: Process S (tau 811ms) completed I/O; added to ready queue [Q Q T C H B K O L A E G J R N D I S M]
time 7148ms: Process F (tau 70ms) completed a CPU burst; 87 bursts to go [Q Q T C H B K O L A E G J R N D I S M]
time 7148ms: Recalculating tau for process F: old tau 70ms ==> new tau 22ms [Q Q T C H B K O L A E G J R N D I S M]
time 7148ms: Process F switching out of CPU; blocking on I/O until time 7200ms [Q Q T C H B K O L A E G J R N D I S M]
time 7152ms: Process Q (tau 89ms) started using the CPU for 268ms burst [Q T C H B K O L A E G J R N D I S M]
time 7200ms: Process F (tau 22ms) completed I/O; preempting Q [Q T C H B K O L A E G J R N D I S M]
time 7204ms: Process F (tau 22ms) started using the CPU for 3ms burst [Q Q T C H B K O L A E G J R N D I S M]
time 7207ms: Process F (tau 22ms) completed a CPU burst; 86 bursts to go [Q Q T C H B K O L A E G J R N D I S M]
time 7207ms: Recalculating tau for process F: old tau 22ms ==> new tau 4ms [Q Q T C H B K O L A E G J R N D I S M]
time 7207ms: Process F switching out of CPU; blocking on I/O until time 10909ms [Q Q T C H B K O L A E G J R N D I S M]
time 7211ms: Process Q (tau 41ms) started using the CPU for 220ms burst [Q T C H B K O L A E G J R N D I S M]
time 7326ms: Process P (tau 259ms) completed I/O; added to ready queue [Q T C H B K O L P A E G J R N D I S M]
time 7431ms: Process Q (tau 89ms) completed a CPU burst; 57 bursts to go [Q T C H B K O L P A E G J R N D I S M]
time 7431ms: Recalculating tau for process Q: old tau 89ms ==> new tau 261ms [Q T C H B K O L P A E G J R N D I S M]
time 7431ms: Process Q switching out of CPU; blocking on I/O until time 7448ms [Q T C H B K O L P A E G J R N D I S M]
time 7435ms: Process T (tau 100ms) started using the CPU for 464ms burst [Q C H B K O L P A E G J R N D I S M]
time 7448ms: Process Q (tau 261ms) completed I/O; added to ready queue [Q C H B K O L P Q A E G J R N D I S M]
time 7899ms: Process T (tau 100ms) completed a CPU burst; 98 bursts to go [Q C H B K O L P Q A E G J R N D I S M]
time 7899ms: Recalculating tau for process T: old tau 100ms ==> new tau 450ms [Q C H B K O L P Q A E G J R N D I S M]
time 7899ms: Process T switching out of CPU; blocking on I/O until time 8208ms [Q C H B K O L P Q A E G J R N D I S M]
time 7903ms: Process C (tau 104ms) started using the CPU for 44ms burst [Q H B K O L P Q A E G J R N D I S M]
time 7947ms: Process C (tau 104ms) completed a CPU burst; 28 bursts to go [Q H B K O L P Q A E G J R N D I S M]
time 7947ms: Recalculating tau for process C: old tau 104ms ==> new tau 47ms [Q H B K O L P Q A E G J R N D I S M]
time 7947ms: Process C switching out of CPU; blocking on I/O until time 8329ms [Q H B K O L P Q A E G J R N D I S M]
time 7951ms: Process H (tau 106ms) started using the CPU for 62ms burst [Q B K O L P Q A E G J R N D I S M]
time 8013ms: Process H (tau 106ms) completed a CPU burst; 40 bursts to go [Q B K O L P Q A E G J R N D I S M]
time 8013ms: Recalculating tau for process H: old tau 106ms ==> new tau 64ms [Q B K O L P Q A E G J R N D I S M]
time 8013ms: Process H switching out of CPU; blocking on I/O until time 12015ms [Q B K O L P Q A E G J R N D I S M]
time 8017ms: Process B (tau 157ms) started using the CPU for 101ms burst [Q K O L P Q A E G J R N D I S M]
time 8118ms: Process B (tau 157ms) completed a CPU burst; 48 bursts to go [Q K O L P Q A E G J R N D I S M]
time 8118ms: Recalculating tau for process B: old tau 157ms ==> new tau 104ms [Q K O L P Q A E G J R N D I S M]
time 8118ms: Process B switching out of CPU; blocking on I/O until time 8370ms [Q K O L P Q A E G J R N D I S M]
time 8122ms: Process K (tau 167ms) started using the CPU for 1100ms burst [Q O L P Q A E G J R N D I S M]
time 8208ms: Process T (tau 450ms) completed I/O; added to ready queue [Q O L P Q A E G J R N D T I S M]
time 8329ms: Process C (tau 47ms) completed I/O; added to ready queue [Q C O L P Q A E G J R N D T I S M]
time 8370ms: Process B (tau 104ms) completed I/O; added to ready queue [Q C B O L P Q A E G J R N D T I S M]
time 9222ms: Process K (tau 167ms) completed a CPU burst; 85 bursts to go [Q C B O L P Q A E G J R N D T I S M]
time 9222ms: Recalculating tau for process K: old tau 167ms ==> new tau 1063ms [Q C B O L P Q A E G J R N D T I S M]
time 9222ms: Process K switching out of CPU; blocking on I/O until time 9461ms [Q C B O L P Q A E G J R N D T I S M]
time 9226ms: Process C (tau 47ms) started using the CPU for 85ms burst [Q B O L P Q A E G J R N D T I S M]
time 9311ms: Process C (tau 47ms) completed a CPU burst; 27 bursts to go [Q B O L P Q A E G J R N D T I S M]
time 9311ms: Recalculating tau for process C: old tau 47ms ==> new tau 84ms [Q B O L P Q A E G J R N D T I S M]
time 9311ms: Process C switching out of CPU; blocking on I/O until time 9963ms [Q B O L P Q A E G J R N D T I S M]
time 9315ms: Process B (tau 104ms) started using the CPU for 426ms burst [Q O L P Q A E G J R N D T I S M]
time 9461ms: Process K (tau 1063ms) completed I/O; added to ready queue [Q O L P Q A E G J R N D T I S K M]
time 9741ms: Process B (tau 104ms) completed a CPU burst; 47 bursts to go [Q O L P Q A E G J R N D T I S K M]
time 9741ms: Recalculating tau for process B: old tau 104ms ==> new tau 414ms [Q O L P Q A E G J R N D T I S K M]
time 9741ms: Process B switching out of CPU; blocking on I/O until time 10243ms [Q O L P Q A E G J R N D T I S K M]
time 9745ms: Process O (tau 196ms) started using the CPU for 4ms burst [Q L P Q A E G J R N D T I S K M]
time 9749ms: Process O (tau 196ms) completed a CPU burst; 1 bursts to go [Q L P Q A E G J R N D T I S K M]
time 9749ms: Recalculating tau for process O: old tau 196ms ==> new tau 12ms [Q L P Q A E G J R N D T I S K M]
time 9749ms: Process O switching out of CPU; blocking on I/O until time 9991ms [Q L P Q A E G J R N D T I S K M]
time 9753ms: Process L (tau 246ms) started using the CPU for 720ms burst [Q P Q A E G J R N D T I S K M]
time 9963ms: Process C (tau 84ms) completed I/O; added to ready queue [Q C P Q A E G J R N D T I S K M]
time 9991ms: Process O (tau 12ms) completed I/O; added to ready queue [Q O C P Q A E G J R N D T I S K M]
time 10773ms: Process O terminated [Q C P Q A E G J R N B D T I L S K M]
time 54848ms: Process C terminated [Q R S T I K M Q L J P]
time 70925ms: Process H terminated [Q E F I T K M S R Q N L J P]
time 81685ms: Process B terminated [Q G A E F D T K M S R Q N L J P]
time 82426ms: Process E terminated [Q F D T K M S R I Q N L J P]
time 101374ms: Process G terminated [Q A M S R T I Q N L K J P]
time 125930ms: Process F terminated [Q T I S R Q N L K J M P]
time 142873ms: Process S terminated [Q A I R Q N L T K J M P]
time 158519ms: Process D terminated [Q A Q N I L T K J M P]
time 158694ms: Process A terminated [Q R Q N I L T K J M P]
time 163909ms: Process N terminated [Q L I Q T K R J M P]
time 195277ms: Process Q terminated [Q K L T R J M P]
time 241011ms: Process I terminated [Q T R J M L P]
time 248734ms: Process T terminated [Q K R J M L P]
time 261147ms: Process M terminated [Q K L P]
time 342300ms: Process K terminated [Q J L R]
time 352887ms: Process L terminated [Q J R]
time 359000ms: Process P terminated [Q R]
time 371570ms: Process R terminated [Q J]
time 371825ms: Simulator ended for SRT [Q <empty>]
